Workbook

Sheet הוראות שימוש
A1: מערכת ניקוד שאלון אורח חיים – הוראות שימוש
A2: מבוסס על שאלונים מאומתים מדעית | לשימוש מקצועי בלבד
B4: כיצד להשתמש במערכת זו?
B5: שלב 1: לשונית 'קלט שאלון' | C5: הזן את תשובות המטופל/ת לפי מספרי השאלות. כל שאלה מסומנת עם הסבר ואפשרויות הניקוד.
B6: שלב 2: לשונית 'ציונים ודחיפות' | C6: המערכת מחשבת אוטומטית את הציונים לכל שאלון, מסמנת בצבע את רמת הדחיפות.
B7: שלב 3: לשונית 'סיכום קליני' | C7: הפקת סיכום מוכן לפגישה עם הממצאים הבולטים, הדגלים האדומים וההמלצות.
B8: שלב 4: לשונית 'גרף רדאר' | C8: ויזואליזציה של פרופיל הבריאות המלא של המטופל/ת בתרשים גרפי.
B9: שלב 5: לשונית 'מדריך שאלונים' | C9: הסבר מדעי על כל שאלון, שיטת החישוב, פרשנות הציונים ומקורות.
B11: מדריך צבעים – רמות דחיפות טיפול
B12: 🚨 חירום מיידי | C12: אלימות במשפחה / מחשבות אובדניות – הפנייה מיידית
B13: 🔴 דחיפות גבוהה | C13: גורם סיכון משמעותי – יש לטפל בפגישה הראשונה
B14: 🟠 דחיפות בינונית-גבוהה | C14: נדרשת התייחסות מהירה – בפגישה הראשונה או השנייה
B15: 🟡 דחיפות בינונית | C15: יש לכלול בתוכנית הטיפול
B16: 🟢 תקין / דחיפות נמוכה | C16: לשמר ולעודד

Sheet קלט שאלון
A1: קלט תשובות השאלון – הזן את תשובות המטופל/ת
A2: תאים כחולים = קלט ידני | תאים אפורים = מחושב אוטומטית
A4: פרטי מטופל/ת
B5: שם מלא
B6: ת.ז.
B7: תאריך לידה
B8: מגדר (ז/נ)
B9: תאריך מילוי השאלון
A11: חלק א׳ – רקע רפואי
A12: 7 | B12: מחלות כרוניות (מס׳) | C12: 0=אין, 1=אחת, 2=שתיים, 3+=שלוש ומעלה | E12: שאלה 7
A13: 12 | B13: היסטוריה משפחתית – לב | C13: 0=לא/לא ידוע, 1=כן | E13: שאלה 12
A14: 13 | B14: היסטוריה משפחתית – סוכרת | C14: 0=לא/לא ידוע, 1=כן | E14: שאלה 13
A15: 14 | B15: היסטוריה משפחתית – לחץ דם | C15: 0=לא/לא ידוע, 1=כן | E15: שאלה 14
A16: 15 | B16: היסטוריה משפחתית – השמנה | C16: 0=לא/לא ידוע, 1=כן | E16: שאלה 15
A17: 16 | B17: היסטוריה משפחתית – סרטן | C17: 0=לא/לא ידוע, 1=כן | E17: שאלה 16
A18: 17 | B18: היסטוריה משפחתית – נפשי | C18: 0=לא/לא ידוע, 1=כן | E18: שאלה 17
A19: חלק ב׳ – תזונה ים-תיכונית (I-MEDAS)
A20: 24 | B20: שמן זית כעיקרי | C20: 1=כן, 0=לא | E20: שאלה 24
A21: 25 | B21: ירקות מנות/יום | C21: מספר מנות (200 גרם) | E21: שאלה 25
A22: 26 | B22: פירות מנות/יום | C22: מספר מנות (125 גרם) | E22: שאלה 26
A23: 27 | B23: קטניות מנות/שבוע | C23: מספר מנות | E23: שאלה 27
A24: 28 | B24: דגים מנות/שבוע | C24: מספר מנות | E24: שאלה 28
A25: 29 | B25: אגוזים מנות/שבוע | C25: מספר מנות | E25: שאלה 29
A26: 30 | B26: דגנים מלאים מנות/יום | C26: מספר מנות | E26: שאלה 30
A27: 31 | B27: מוצרי חלב לא ממותקים/יום | C27: מספר מנות | E27: שאלה 31
A28: 32 | B28: עוף/הודו מנות/שבוע | C28: מספר מנות | E28: שאלה 32
A29: 33 | B29: בשר אדום/מעובד מנות/שבוע | C29: מספר מנות | E29: שאלה 33
A30: 34 | B30: חמאה/מרגרינה מנות/יום | C30: מספר מנות | E30: שאלה 34
A31: 35 | B31: משקאות ממותקים כוסות/יום | C31: מספר כוסות | E31: שאלה 35
... A38: 42 | B38: מטוגן עמוק פעמים/שבוע | C38: מספר פעמים | E38: שאלה 42
A39: חלק ב׳ב – דפוסי אכילה (TFEQ)
A40: 44 | B40: TFEQ: קושי לעצור אכילה | C40: 1=בהחלט לא, 2=ברוב לא, 3=ברוב כן, 4=בהחלט כן | E40: שאלה 44
A41: 45 | B41: TFEQ: אכילה רגשית | C41: 1=בהחלט לא, 2=ברוב לא, 3=ברוב כן, 4=בהחלט כן | E41: שאלה 45
A42: 46 | B42: TFEQ: הגבלה קוגניטיבית | C42: 1=בהחלט לא, 2=ברוב לא, 3=ברוב כן, 4=בהחלט כן | E42: שאלה 46
A43: 47 | B43: TFEQ: אכילה למראה אוכל | C43: 1=בהחלט לא, 2=ברוב לא, 3=ברוב כן, 4=בהחלט כן | E43: שאלה 47
A44: 48 | B44: TFEQ: שובע בסיום ארוחה | C44: 1=כמעט אף פעם, 2=לפעמים, 3=לעיתים קרובות, 4=כמעט תמיד | E44: שאלה 48
A45: חלק ג׳ – פעילות גופנית (IPAQ)
A46: 49 | B46: ימי פעילות אירובית/שבוע | C46: מספר ימים (0-7) | E46: שאלה 49
A47: 50 | B47: דקות פעילות אירובית/יום | C47: מספר דקות | E47: שאלה 50
A48: 51 | B48: פעמי אימוני כוח/שבוע | C48: מספר פעמים (0-7) | E48: שאלה 51
...

Sheet ציונים ודחיפות
A1: ציונים, פרשנות ודחיפות טיפול – מחושב אוטומטית
A2: כל הציונים מתעדכנים אוטומטית עם הזנת הנתונים בלשונית 'קלט שאלון'
A3: # | B3: שאלון / תחום | C3: ציון גולמי | D3: ניקוד מנורמל (0–100) | E3: פרשנות | F3: דחיפות טיפול | G3: מקור
A4: 1 | B4: היסטוריה משפחתית | C4: ='קלט שאלון'!D13+'קלט שאלון'!D14+'קלט שאלון'!D15+'קלט שאלון'!D16+'קלט שאלון'!D17+'קלט שאלון'!D18 -> 0 | D4: =IF(ISNUMBER(C4),ROUND(C4/6*100,0),"") -> 0 | E4: =IF(ISNUMBER(C4),IF(C4>=3,"מספר גורמי סיכון גבוה",IF(C4>=1,"גורם סיכון אחד לפחות","תקין")),"–") -> תקין | F4: =IF(ISNUMBER(C4),IF(C4>=3,"🔴 דחיפות גבוהה",IF(C4>=1,"🟡 בינונית","🟢 תקין")),"–") -> 🟢 תקין | G4: Piepoli et al., 2016
A5: 2 | B5: תזונה ים-תיכונית (I-MEDAS) | C5: =IF(ISNUMBER('קלט שאלון'!D20),IF('קלט שאלון'!D20=1,1,0),0)+IF(ISNUMBER('קלט שאלון'!D21),IF('קלט שאלון'!D21>=2,1,0),0)+IF(ISNUMBER('קלט שאלון'!D22),IF('קלט שאלון'!D22>=3,1,0),0)+IF(ISNUMBER('קלט שאלון'!D23),IF('קלט שאלון'!D23>=3,1,0),0)+IF(ISNUMBER('קלט שאלון'!D24),IF('קלט שאלון'!D24>=3,1,0),0)+IF(ISNUMBER('קלט שאלון'!D25),IF('קלט שאלון'!D25>=3,1,0),0)+IF(ISNUMBER('קלט שאלון'!D26),IF('קלט שאלון'!D26>=2,1,0),0)+IF(ISNUMBER('קלט שאלון'!D27),IF('קלט שאלון'!D27>=2,1,0),0)+IF(ISNUMBER('קלט שאלון'!D28),IF('קלט שאלון'!D28>=2,1,0),0)+IF(ISNUMBER('קלט שאלון'!D29),IF('קלט שאלון'!D29<=7,1,0),0)+IF(ISNUMBER('קלט שאלון'!D30),IF('קלט שאלון'!D30<=1,1,0),0)+IF(ISNUMBER('קלט שאלון'!D31),IF('קלט שאלון'!D31<=1,1,0),0)+IF(ISNUMBER('קלט שאלון'!D32),IF('קלט שאלון'!D32<=7,1,0),0)+IF(ISNUMBER('קלט שאלון'!D33),IF('קלט שאלון'!D33<=2,1,0),0)+IF(ISNUMBER('קלט שאלון'!D34),IF('קלט שאלון'!D34<=2,1,0),0)+IF(ISNUMBER('קלט שאלון'!D35),IF('קלט שאלון'!D35<=3,1,0),0)+IF(ISNUMBER('קלט שאלון'!D36),IF('קלט שאלון'!D36<=2,1,0),0) -> 0 | D5: =IF(ISNUMBER(C5),ROUND(C5/17*100,0),"") -> 0 | E5: =IF(ISNUMBER(C5),IF(C5>=14,"מצוינת",IF(C5>=10,"טובה",IF(C5>=6,"בינונית","לא ים-תיכונית"))),"–") -> לא ים-תיכונית | F5: =IF(ISNUMBER(C5),IF(C5<=5,"🔴 דחיפות גבוהה",IF(C5<=9,"🟠 בינונית-גבוהה",IF(C5<=13,"🟡 בינונית","🟢 תקין"))),"–") -> 🔴 דחיפות גבוהה | G5: Martínez-González et al., 2012
A6: 3a | B6: אכילה לא מבוקרת (TFEQ-UE) | C6: =IF(ISNUMBER('קלט שאלון'!D40),ROUND(('קלט שאלון'!D40+(5-'קלט שאלון'!D44))/8*100,0),"") | D6: =C6 | E6: =IF(ISNUMBER(C6),IF(C6>=75,"גבוהה מאד",IF(C6>=50,"גבוהה",IF(C6>=25,"בינונית","נמוכה"))),"–") -> – | F6: =IF(ISNUMBER(C6),IF(C6>=50,"🔴 דחיפות גבוהה",IF(C6>=25,"🟡 בינונית","🟢 תקין")),"–") -> – | G6: Karlsson et al., 2000
A7: 3b | B7: אכילה רגשית (TFEQ-EE) | C7: =IF(ISNUMBER('קלט שאלון'!D41),ROUND(('קלט שאלון'!D41+'קלט שאלון'!D43)/8*100,0),"") | D7: =C7 | E7: =IF(ISNUMBER(C7),IF(C7>=75,"גבוהה מאד",IF(C7>=50,"גבוהה",IF(C7>=25,"בינונית","נמוכה"))),"–") -> – | F7: =IF(ISNUMBER(C7),IF(C7>=50,"🔴 דחיפות גבוהה",IF(C7>=25,"🟡 בינונית","🟢 תקין")),"–") -> – | G7: Karlsson et al., 2000
A8: 4 | B8: פעילות גופנית (IPAQ – MET-דק׳/שבוע) | C8: =IF(ISNUMBER('קלט שאלון'!D46),ROUND('קלט שאלון'!D46*'קלט שאלון'!D47*4,0),"") | D8: =IF(ISNUMBER(C8),ROUND(MIN(C8/3000*100,100),0),"") | E8: =IF(ISNUMBER(C8),IF(C8>=3000,"גבוה",IF(C8>=600,"בינוני","נמוך – Inactive")),"–") -> – | F8: =IF(ISNUMBER(C8),IF(C8<600,"🔴 דחיפות גבוהה",IF(C8<3000,"🟡 בינונית","🟢 תקין")),"–") -> – | G8: Craig et al., 2003
A9: 5 | B9: זמן ישיבה (שעות/יום) | C9: ='קלט שאלון'!D49 -> 0 | D9: =IF(ISNUMBER(C9),ROUND(MAX(0,(C9-4)/14*100),0),"") -> 0 | E9: =IF(ISNUMBER(C9),IF(C9>10,"גבוה מאד",IF(C9>8,"גבוה",IF(C9>6,"בינוני","תקין"))),"–") -> תקין | F9: =IF(ISNUMBER(C9),IF(C9>8,"🟠 בינונית-גבוהה",IF(C9>6,"🟡 בינונית","🟢 תקין")),"–") -> 🟢 תקין | G9: Biswas et al., 2015
A10: 6 | B10: שינה (PSQI – ציון חלקי) | C10: =IF(ISNUMBER('קלט שאלון'!D56),IF(ISNUMBER('קלט שאלון'!D54),IF('קלט שאלון'!D54<=15,0,IF('קלט שאלון'!D54<=30,1,IF('קלט שאלון'!D54<=60,2,3))),0)+IF(ISNUMBER('קלט שאלון'!D56),IF('קלט שאלון'!D56>7,0,IF('קלט שאלון'!D56>=6,1,IF('קלט שאלון'!D56>=5,2,3))),0)+'קלט שאלון'!D58,"") | D10: =IF(ISNUMBER(C10),ROUND(C10/9*100,0),"") | E10: =IF(ISNUMBER(C10),IF(C10>=7,"הפרעת שינה חמורה",IF(C10>=5,"הפרעת שינה בינונית","שינה תקינה")),"–") -> – | F10: =IF(ISNUMBER(C10),IF(C10>=7,"🔴 דחיפות גבוהה",IF(C10>=5,"🟠 בינונית-גבוהה","🟢 תקין")),"–") -> – | G10: Buysse et al., 1989
A11: 7 | B11: תלות בניקוטין (FTND) | C11: =IF('קלט שאלון'!D61=2,'קלט שאלון'!D62+'קלט שאלון'!D63,0) -> 0 | D11: =IF(ISNUMBER(C11),IF('קלט שאלון'!D61=2,ROUND(C11/6*100,0),0),"") -> 0 | E11: =IF('קלט שאלון'!D61=2,IF(C11>=6,"תלות גבוהה",IF(C11>=5,"תלות בינונית",IF(C11>=3,"תלות נמוכה","תלות נמוכה מאד"))),"אינו מעשן/ת") -> אינו מעשן/ת | F11: =IF('קלט שאלון'!D61=2,IF(C11>=6,"🔴 דחיפות גבוהה",IF(C11>=3,"🟠 בינונית-גבוהה","🟡 בינונית")),"🟢 תקין") -> 🟢 תקין | G11: Heatherton et al., 1991
A12: 8 | B12: שתיית אלכוהול (AUDIT-C) | C12: =IF(ISNUMBER('קלט שאלון'!D67),'קלט שאלון'!D67+'קלט שאלון'!D68+'קלט שאלון'!D69,"") | D12: =IF(ISNUMBER(C12),ROUND(C12/12*100,0),"") | E12: =IF(ISNUMBER(C12),IF(C12>=8,"שתייה מסוכנת",IF(C12>=4,"שתייה מסוכנת (גברים) / בסיכון (נשים)","תקין")),"–") -> – | F12: =IF(ISNUMBER(C12),IF(C12>=4,"🔴 דחיפות גבוהה",IF(C12>=3,"🟠 בינונית-גבוהה","🟢 תקין")),"–") -> – | G12: Bush et al., 1998
A13: 9 | B13: סטרס נתפש (PSS-10 קצר) | C13: =IF(ISNUMBER('קלט שאלון'!D74),'קלט שאלון'!D74+(4-'קלט שאלון'!D75)+'קלט שאלון'!D76+(4-'קלט שאלון'!D77)+'קלט שאלון'!D78,"") | D13: =IF(ISNUMBER(C13),ROUND(C13/20*100,0),"") | E13: =IF(ISNUMBER(C13),IF(C13>=12,"סטרס גבוה",IF(C13>=8,"סטרס בינוני","סטרס נמוך")),"–") -> – | F13: =IF(ISNUMBER(C13),IF(C13>=12,"🔴 דחיפות גבוהה",IF(C13>=8,"🟡 בינונית","🟢 תקין")),"–") -> – | G13: Cohen et al., 1983
A14: 10 | B14: דיכאון וחרדה (PHQ-4) | C14: =IF(ISNUMBER('קלט שאלון'!D80),'קלט שאלון'!D80+'קלט שאלון'!D81+'קלט שאלון'!D82+'קלט שאלון'!D83,"") | D14: =IF(ISNUMBER(C14),ROUND(C14/12*100,0),"") | E14: =IF(ISNUMBER(C14),IF(C14>=9,"חמור",IF(C14>=6,"בינוני",IF(C14>=3,"קל","תקין"))),"–") -> – | F14: =IF(ISNUMBER(C14),IF(C14>=6,"🔴 דחיפות גבוהה – הפנייה",IF(C14>=3,"🟠 בינונית-גבוהה","🟢 תקין")),"–") -> – | G14: Kroenke et al., 2009
A15: 11 | B15: תמיכה חברתית (MOS) | C15: =IF(ISNUMBER('קלט שאלון'!D85),ROUND(((6-'קלט שאלון'!D85)+('קלט שאלון'!D86-1)+('קלט שאלון'!D87-1))/(3+8)*100,0),"") | D15: =C15 | E15: =IF(ISNUMBER(C15),IF(C15>=67,"תמיכה טובה",IF(C15>=34,"תמיכה בינונית","בידוד חברתי")),"–") -> – | F15: =IF(ISNUMBER(C15),IF(C15<34,"🟠 בינונית-גבוהה",IF(C15<67,"🟡 בינונית","🟢 תקין")),"–") -> – | G15: Sherbourne & Stewart, 1991
A16: 12 | B16: אלימות במשפחה (PVS/HITS) | C16: =IF(ISNUMBER('קלט שאלון'!D89),'קלט שאלון'!D89+'קלט שאלון'!D90+'קלט שאלון'!D91+'קלט שאלון'!D92,"") | D16: =IF(ISNUMBER(C16),IF(C16>0,100,0),"") | E16: =IF(ISNUMBER(C16),IF(C16>0,"דגל אדום – נדרשת התייחסות מיידית","ללא אינדיקציה"),"–") -> – | F16: =IF(ISNUMBER(C16),IF(C16>0,"🚨 חירום מיידי","🟢 ללא ממצא"),"–") -> – | G16: Feldhaus et al., 1997
A17: 13 | B17: מוטיבציה ושלב שינוי | C17: ='קלט שאלון'!D94 -> 0 | D17: =IF(ISNUMBER(C17),ROUND((C17-1)/4*100,0),"") -> -25 | E17: =IF(ISNUMBER('קלט שאלון'!D95),CHOOSE('קלט שאלון'!D95,"טרום-מחשבה","מחשבה","הכנה","פעולה (כשל קודם)","פעולה פעילה"),"–") -> – | F17: =IF(ISNUMBER('קלט שאלון'!D94),IF('קלט שאלון'!D94<=2,"🟠 מוטיבציה נמוכה",IF('קלט שאלון'!D94<=3,"🟡 בינונית","🟢 מוטיבציה גבוהה")),"–") -> – | G17: Prochaska & DiClemente, 1983

Sheet סיכום קליני
A1: סיכום קליני – מוכן לפגישה עם הדיאטנ/ית
A2: מתעדכן אוטומטית מלשונית 'קלט שאלון'
A3: פרטי מטופל/ת
B4: שם | C4: ='קלט שאלון'!C5 -> 0
B5: ת.ז. | C5: ='קלט שאלון'!C6 -> 0
B6: תאריך לידה | C6: ='קלט שאלון'!C7 -> 0
B7: מגדר | C7: ='קלט שאלון'!C8 -> 0
B8: תאריך מילוי | C8: ='קלט שאלון'!C9 -> 0
A10: לוח בקרה – סיכום ציונים ודחיפות
A11: תחום | B11: ציון | C11: פרשנות | D11: דחיפות | E11: המלצה ראשונית
A12: היסטוריה משפחתית | B12: ='ציונים ודחיפות'!C4 -> 0 | C12: ='ציונים ודחיפות'!E4 -> תקין | D12: ='ציונים ודחיפות'!F4 -> 🟢 תקין | E12: לבדוק גורמי סיכון קרדיו-מטבוליים
A13: תזונה ים-תיכונית | B13: ='ציונים ודחיפות'!C5 -> 0 | C13: ='ציונים ודחיפות'!E5 -> לא ים-תיכונית | D13: ='ציונים ודחיפות'!F5 -> 🔴 דחיפות גבוהה | E13: מיפוי הרגלים תזונתיים + תכנית ים-תיכונית
A14: אכילה לא מבוקרת | B14: ='ציונים ודחיפות'!D6 | C14: ='ציונים ודחיפות'!E6 -> – | D14: ='ציונים ודחיפות'!F6 -> – | E14: טכניקות אכילה מודעת (Mindful Eating)
A15: אכילה רגשית | B15: ='ציונים ודחיפות'!D7 | C15: ='ציונים ודחיפות'!E7 -> – | D15: ='ציונים ודחיפות'!F7 -> – | E15: הפנייה לטיפול פסיכולוגי / CBT
A16: פעילות גופנית | B16: ='ציונים ודחיפות'!C8 | C16: ='ציונים ודחיפות'!E8 -> – | D16: ='ציונים ודחיפות'!F8 -> – | E16: תכנית אימונים + הפחתת ישיבה
A17: זמן ישיבה | B17: ='ציונים ודחיפות'!C9 -> 0 | C17: ='ציונים ודחיפות'!E9 -> תקין | D17: ='ציונים ודחיפות'!F9 -> 🟢 תקין | E17: הפסקות תנועה כל 45–60 דקות
A18: שינה | B18: ='ציונים ודחיפות'!C10 | C18: ='ציונים ודחיפות'!E10 -> – | D18: ='ציונים ודחיפות'!F10 -> – | E18: היגיינת שינה + הפחתת מסכים
A19: עישון | B19: ='ציונים ודחיפות'!C11 -> 0 | C19: ='ציונים ודחיפות'!E11 -> אינו מעשן/ת | D19: ='ציונים ודחיפות'!F11 -> 🟢 תקין | E19: הפנייה לקייטנת גמילה מעישון
A20: אלכוהול | B20: ='ציונים ודחיפות'!C12 | C20: ='ציונים ודחיפות'!E12 -> – | D20: ='ציונים ודחיפות'!F12 -> – | E20: הפנייה – AUDIT-C חיובי
A21: סטרס | B21: ='ציונים ודחיפות'!C13 | C21: ='ציונים ודחיפות'!E13 -> – | D21: ='ציונים ודחיפות'!F13 -> – | E21: טכניקות ניהול סטרס / מיינדפולנס
A22: דיכאון וחרדה | B22: ='ציונים ודחיפות'!C14 | C22: ='ציונים ודחיפות'!E14 -> – | D22: ='ציונים ודחיפות'!F14 -> – | E22: הפנייה לפסיכולוג/פסיכיאטר
A23: תמיכה חברתית | B23: ='ציונים ודחיפות'!C15 | C23: ='ציונים ודחיפות'!E15 -> – | D23: ='ציונים ודחיפות'!F15 -> – | E23: חיזוק רשת תמיכה + קבוצות תמיכה
A24: אלימות במשפחה | B24: ='ציונים ודחיפות'!C16 | C24: ='ציונים ודחיפות'!E16 -> – | D24: ='ציונים ודחיפות'!F16 -> – | E24: 🚨 פרוטוקול אלימות – הפנייה מיידית
A25: מוטיבציה לשינוי | B25: ='ציונים ודחיפות'!C17 -> 0 | C25: ='ציונים ודחיפות'!E17 -> – | D25: ='ציונים ודחיפות'!F17 -> – | E25: התאמת גישה טיפולית לשלב השינוי
A28: סדר עדיפויות לפגישה – עפ״י רמת הדחיפות
A29: 🚨 עדיפות 1 – חירום מיידי | B29: אלימות במשפחה / PHQ-4 חמור
A30: 🔴 עדיפות 2 – דחיפות גבוהה | B30: גורמי סיכון קרדיו-מטבוליים (תזונה, עישון, אלכוהול, PSS)
A31: 🟠 עדיפות 3 – בינונית-גבוהה | B31: שינה, פעילות גופנית, PHQ-4 קל-בינוני
A32: 🟡 עדיפות 4 – בינונית | B32: דפוסי אכילה, זמן ישיבה, תמיכה חברתית
A33: 🟢 עדיפות 5 – שמירה | B33: חיזוק הרגלים חיוביים קיימים

Sheet גרף רדאר
A1: פרופיל בריאות – ציונים מנורמלים (0–100)
A2: תחום | B2: ציון (0-100) | C2: יעד
A3: תזונה | B3: ='ציונים ודחיפות'!D5 -> 0 | C3: 80
A4: פעילות גופנית | B4: ='ציונים ודחיפות'!D8 | C4: 80
A5: שינה | B5: ='ציונים ודחיפות'!D10 | C5: 80
A6: ניהול סטרס | B6: =IFERROR(MAX(0,100-'ציונים ודחיפות'!D13),0) -> 0 | C6: 80
A7: בריאות נפשית | B7: =IFERROR(MAX(0,100-'ציונים ודחיפות'!D14),0) -> 0 | C7: 80
A8: תמיכה חברתית | B8: ='ציונים ודחיפות'!D15 | C8: 80
A9: אכילה מבוקרת | B9: =IFERROR(MAX(0,100-'ציונים ודחיפות'!D6),0) -> 0 | C9: 80
A10: ללא עישון | B10: =MAX(0,100-'ציונים ודחיפות'!D11) -> 100 | C10: 80
A11: ללא אלכוהול | B11: =IFERROR(MAX(0,100-'ציונים ודחיפות'!D12),0) -> 0 | C11: 80
A12: מוטיבציה | B12: ='ציונים ודחיפות'!D17 -> -25 | C12: 80
